<?xml version='1.0'?>

<sdf version='1.4'>


   <model name="diffdrive">

  <static>false</static>

   <link name='chassis'>
     <pose>0 0 0.1 0 0 0</pose>

   <inertial>
     <mass>10.0</mass>
     <pose>0.0 0 0.1 0 0 0</pose>
     <inertia>
     <ixx>0.5</ixx>
     <iyy>1.0</iyy>
     <izz>0.1</izz>
     </inertia>
    </inertial>
   
    <collision name='collision'>
       <geometry>
       <box>
       <size>.4 .2 .1</size>
       </box>
       </geometry>
     </collision>

    <visual name='visual'>
      <pose>0 0 0.0 0 0 0</pose>
      <geometry>
      <box>
      <size>.4 .2 .1</size>
      </box>
      </geometry>
    </visual>

	<collision name='caster_collision'>
	 <pose>-0.15 0 -0.05 0 0 0</pose>
	 <geometry>
	 <sphere>
	 <radius>.05</radius>
	 </sphere>
	 </geometry>
	
	 <surface>
	 <friction>
	 <ode>
	 <mu>0</mu>
	 <mu2>0</mu2>
	 <slip1>1.0</slip1>
	 <slip2>1.0</slip2>
	 </ode>
	 </friction>
	 </surface>
	 </collision>

	<visual name='caster_visual'>
	 <pose>-0.15 0 -0.05 0 0 0</pose>
	 <geometry>
	 <sphere>
	 <radius>.05</radius>
	 </sphere>
	 </geometry>
	 </visual>
	
	</link>
	
<link name="left_wheel">
 <pose>0.1 0.13 0.1 0 1.5707 1.5707</pose>
 <collision name="collision">
 <geometry>
 <cylinder>
 <radius>.1</radius>
 <length>.05</length>
 </cylinder>
 </geometry>
 </collision>
 <visual name="visual">
 <geometry>
 <cylinder>
 <radius>.1</radius>
 <length>.05</length>
 </cylinder>
 </geometry>
 <material> 
    <ambient>1 1 1 1</ambient>
    <diffuse>1 1 1 1</diffuse>
    <specular>1 1 1 1</specular>
    <emissive>0 0 0 0</emissive>
 </material>  
</visual>
 </link>

<joint type="revolute" name="left_wheel_hinge">
 <pose>0 0 -0.03 0 0 0</pose>
 <child>left_wheel</child>
 <parent>chassis</parent>
 <axis>
 <xyz>0 1 0</xyz>
 </axis>
 </joint>


<link name="right_wheel">
 <pose>0.1 -0.13 0.1 0 1.5707 1.5707</pose>
 <collision name="collision">
 <geometry>
 <cylinder>
 <radius>.1</radius>
 <length>.05</length>
 </cylinder>
 </geometry>
 </collision>
 <visual name="visual">
 <geometry>
 <cylinder>
 <radius>.1</radius>
 <length>.05</length>
 </cylinder>
 </geometry>
 <material>  
    <ambient>1 1 1 1</ambient>
    <diffuse>1 1 1 1</diffuse>
    <specular>1 1 1 1</specular>
    <emissive>0 0 0 0</emissive>
 </material>  
 </visual>
 </link>

<joint type="revolute" name="right_wheel_hinge">
 <pose>0 0 0.03 0 0 0</pose>
 <child>right_wheel</child>
 <parent>chassis</parent>
 <axis>
 <xyz>0 1 0</xyz>
 </axis>
 </joint>




<plugin name="differential_drive_controller" filename="libgazebo_ros_diff_drive.so">
 <alwaysOn>true</alwaysOn>
 <updateRate>20</updateRate>
 <leftJoint>left_wheel_hinge</leftJoint>
 <rightJoint>right_wheel_hinge</rightJoint>
 <wheelSeparation>0.4</wheelSeparation>
 <wheelDiameter>0.1</wheelDiameter>
 <torque>20</torque>
 <commandTopic>cmd_vel</commandTopic>
 <odometryTopic>odom</odometryTopic>
 <odometryFrame>odom</odometryFrame>
 <robotBaseFrame>base_footprint</robotBaseFrame>
 </plugin>


	<!-- Joint for the Camera and the "optical frame"-->

<!--
      <joint name="camera_optical_joint" type="fixed">
        <origin xyz="0 0 0" rpy="-1.571 0 -1.571" />
        <parent link="camera_link" />
        <child link="camera_link_optical" />
    </joint>
	

     <link name="camera_link_optical"></link>
-->

      <link name='camera_link'>
   	<pose>0.15 0 0.25 0 -0.35 0</pose>
        <visual name='visual'>
          <geometry>
            <box>
              <size>0.1 0.1 0.1</size>
            </box>
          </geometry>
          <material name="white" />
        </visual>
        <sensor name='my_camera' type='camera'>
	  <update_rate>30</update_rate>
	  <!--<visualize>true</visualize>-->
          <camera>
            <save enabled="true">
              <path>/tmp/camera_save</path>
            </save>
            <horizontal_fov>1.047</horizontal_fov>
            <image>
              <width>1920</width>
              <height>1080</height>
            </image>
            <clip>
              <near>0.1</near>
              <far>100</far>
            </clip>
          </camera>
	  <always_on>1</always_on>

 	   <!-- Include plugin for Publishing ROS Topics-->
           <plugin name="camera_controller" filename="libgazebo_ros_camera.so">
                <frame_name>camera_link_optical</frame_name>
                <min_depth>0.1</min_depth>
                <max_depth>500</max_depth>
            </plugin>

        </sensor>
    </link>

<joint type="fixed" name="chassis_cam">
   <pose>1 1 1 0 -0.35 0</pose>
   <child>camera_link</child>
 <parent>chassis</parent>
 </joint>



   
    </model>
   
</sdf>
